<?xml version="1.0" ?>
<!-- =================================================================================== -->
<!-- |    This document was autogenerated by xacro from nimbro_new.xacro               | -->
<!-- |    EDITING THIS FILE BY HAND IS NOT RECOMMENDED                                 | -->
<!-- =================================================================================== -->
<robot name="nimbro_new">
  <!-- Materials -->
  <material name="black">
    <color rgba="0.1 0.1 0.1 1"/>
  </material>
  <material name="white">
    <color rgba="0.8 0.8 0.8 1"/>
  </material>
  <material name="clear">
    <color rgba="1.0 1.0 1.0 0.0"/>
  </material>
  <material name="orange">
    <color rgba="1.0 0.4235294117647059 0.0392156862745098 1.0"/>
  </material>
  <!-- Joints and links -->
  <link name="trunk_link">
    <inertial>
      <origin rpy="0 0 0" xyz="-0.02658535 0 0.14500787"/>
      <mass value="5.20047716"/>
      <inertia ixx="0.07326504" ixy="0.0" ixz="0.0" iyy="0.07407370" iyz="0.0" izz="0.02367380"/>
    </inertial>
    <visual>
      <origin rpy="0 0 0 " xyz="0 0 0"/>
      <geometry>
        <mesh filename="package://nimbro_op_model/mesh/nimbro_new/trunk_link.STL"/>
      </geometry>
      <material name="white"/>
    </visual>
    <collision>
      <origin rpy="0 0 0" xyz="0 0 0"/>
      <geometry>
        <mesh filename="package://nimbro_op_model/mesh/nimbro_new/trunk_link.STL"/>
      </geometry>
    </collision>
  </link>
  <link name="right_hip_yaw_link">
    <inertial>
      <origin rpy="0 0 0" xyz="0 0.00724195 -0.02181654"/>
      <mass value="0.08195131"/>
      <inertia ixx="0.00005602" ixy="0.0" ixz="-0.00000001" iyy="0.00011377" iyz="0.00000334" izz="0.00010391"/>
    </inertial>
    <visual>
      <origin rpy="0 0 0" xyz="0 0 0"/>
      <geometry>
        <mesh filename="package://nimbro_op_model/mesh/nimbro_new/left_hip_yaw_link.STL" scale="1.0 -1.0 1.0"/>
      </geometry>
      <material name="white"/>
    </visual>
    <collision>
      <origin rpy="0 0 0" xyz="0 0 0"/>
      <geometry>
        <mesh filename="package://nimbro_op_model/mesh/nimbro_new/left_hip_yaw_link.STL" scale="1.0 -1.0 1.0"/>
      </geometry>
    </collision>
  </link>
  <joint name="right_hip_yaw" type="continuous">
    <origin rpy="-0.261799388 0 0" xyz="0 -0.051355805 -0.01071788"/>
    <parent link="trunk_link"/>
    <child link="right_hip_yaw_link"/>
    <axis xyz="0 0 1"/>
  </joint>
  <link name="right_hip_roll_link">
    <inertial>
      <origin rpy="0 0 0" xyz="0.00076574 -0.05251558 0.00065619"/>
      <mass value="1.43634161"/>
      <inertia ixx="0.00462564" ixy="-0.00008808" ixz="-0.00001887" iyy="0.00094964" iyz="0.00002958" izz="0.00464908"/>
    </inertial>
    <visual>
      <origin rpy="0 0 0" xyz="0 0 0"/>
      <geometry>
        <mesh filename="package://nimbro_op_model/mesh/nimbro_new/left_hip_link.STL" scale="1.0 -1.0 1.0"/>
      </geometry>
      <material name="black"/>
    </visual>
    <collision>
      <origin rpy="0 0 0" xyz="0 0 0"/>
      <geometry>
        <mesh filename="package://nimbro_op_model/mesh/nimbro_new/left_hip_link.STL" scale="1.0 -1.0 1.0"/>
      </geometry>
    </collision>
  </link>
  <joint name="right_hip_roll" type="continuous">
    <origin rpy="0 0 0" xyz="0 0 -0.057408771126"/>
    <parent link="right_hip_yaw_link"/>
    <child link="right_hip_roll_link"/>
    <axis xyz="1 0 0"/>
  </joint>
  <link name="right_thigh_link">
    <inertial>
      <origin rpy="0 0 0" xyz="0.01970977 0.00209924 -0.12743050"/>
      <mass value="0.45418350"/>
      <inertia ixx="0.00608556" ixy="-0.00000866" ixz="0.00001934" iyy="0.00585037" iyz="-0.00010098" izz="0.00141334"/>
    </inertial>
    <!-- Use parallel link visuals<visual>
				<origin xyz="0 0 0" rpy="0 0 0" />
				<geometry>
					<mesh filename="package://nimbro_op_model/mesh/${display_variant}/right_thigh_link.STL" />
				</geometry>
				<material name="white" />
			</visual>-->
    <collision>
      <origin rpy="0 0 0" xyz="0 0 0"/>
      <geometry>
        <mesh filename="package://nimbro_op_model/mesh/nimbro_new/left_thigh_link.STL" scale="1.0 -1.0 1.0"/>
      </geometry>
    </collision>
  </link>
  <joint name="right_hip_pitch" type="continuous">
    <origin rpy="0 0 0" xyz="-0.00255 -0.1014 0"/>
    <parent link="right_hip_roll_link"/>
    <child link="right_thigh_link"/>
    <axis xyz="0 1 0"/>
  </joint>
  <link name="right_shank_link">
    <inertial>
      <origin rpy="0 0 0" xyz="0.01748220 0.00011553 -0.10458745"/>
      <mass value="0.31908091"/>
      <inertia ixx="0.00321630" ixy="-0.00000043" ixz="-0.00009814" iyy="0.00296736" iyz="-0.00000589" izz="0.00064089"/>
    </inertial>
    <!-- Use parallel link visuals<visual>
				<origin xyz="0 0 0" rpy="0 0 0" />
				<geometry>
					<mesh filename="package://nimbro_op_model/mesh/${display_variant}/right_shank_link.STL" />
				</geometry>
				<material name="white" />
			</visual>-->
    <collision>
      <origin rpy="0 0 0" xyz="0 0 0"/>
      <geometry>
        <mesh filename="package://nimbro_op_model/mesh/nimbro_new/left_shank_link.STL" scale="1.0 -1.0 1.0"/>
      </geometry>
    </collision>
  </link>
  <joint name="right_knee_pitch" type="continuous">
    <origin rpy="0 0 0" xyz="0 0 -0.27"/>
    <parent link="right_thigh_link"/>
    <child link="right_shank_link"/>
    <axis xyz="0 1 0"/>
  </joint>
  <link name="right_ankle_link">
    <inertial>
      <origin rpy="0 0 0" xyz="0.02809098 -0.00090749 -0.06129945"/>
      <mass value="0.27529515"/>
      <inertia ixx="0.00020315" ixy="0.00000109" ixz="0.00008239" iyy="0.00050134" iyz="0.00001126" izz="0.00049365"/>
    </inertial>
    <!-- Use parallel link visuals<visual>
				<origin xyz="0 0 0" rpy="0 0 0" />
				<geometry>
					<mesh filename="package://nimbro_op_model/mesh/${display_variant}/right_ankle_link.STL" />
				</geometry>
				<material name="white" />
			</visual>-->
    <collision>
      <origin rpy="0 0 0" xyz="0 0 0"/>
      <geometry>
        <mesh filename="package://nimbro_op_model/mesh/nimbro_new/left_ankle_link.STL" scale="1.0 -1.0 1.0"/>
      </geometry>
    </collision>
  </link>
  <joint name="right_ankle_pitch" type="continuous">
    <origin rpy="0 0 0" xyz="0 0 -0.27"/>
    <parent link="right_shank_link"/>
    <child link="right_ankle_link"/>
    <axis xyz="0 1 0"/>
  </joint>
  <link name="right_foot_link">
		</link>
  <joint name="right_ankle_roll" type="continuous">
    <origin rpy="0 0 0" xyz="0 0 0"/>
    <parent link="right_ankle_link"/>
    <child link="right_foot_link"/>
    <axis xyz="1 0 0"/>
  </joint>
  <link name="right_foot_plane_link">
		</link>
  <joint name="right_foot_plane_joint" type="fixed">
    <origin rpy="0 0 0" xyz="0.04562 0 -0.055"/>
    <parent link="right_foot_link"/>
    <child link="right_foot_plane_link"/>
  </joint>
  <link name="left_hip_yaw_link">
    <inertial>
      <origin rpy="0 0 0" xyz="0 -0.00724195 -0.02181654"/>
      <mass value="0.08195131"/>
      <inertia ixx="0.00005602" ixy="0.0" ixz="-0.00000001" iyy="0.00011377" iyz="0.00000334" izz="0.00010391"/>
    </inertial>
    <visual>
      <origin rpy="0 0 0" xyz="0 0 0"/>
      <geometry>
        <mesh filename="package://nimbro_op_model/mesh/nimbro_new/left_hip_yaw_link.STL"/>
      </geometry>
      <material name="white"/>
    </visual>
    <collision>
      <origin rpy="0 0 0" xyz="0 0 0"/>
      <geometry>
        <mesh filename="package://nimbro_op_model/mesh/nimbro_new/left_hip_yaw_link.STL"/>
      </geometry>
    </collision>
  </link>
  <joint name="left_hip_yaw" type="continuous">
    <origin rpy="0.261799388 0 0" xyz="0 0.051355805 -0.01071788"/>
    <parent link="trunk_link"/>
    <child link="left_hip_yaw_link"/>
    <axis xyz="0 0 1"/>
  </joint>
  <link name="left_hip_roll_link">
    <inertial>
      <origin rpy="0 0 0" xyz="0.00076574 0.05251558 0.00065619"/>
      <mass value="1.43634161"/>
      <inertia ixx="0.00462564" ixy="0.00008808" ixz="-0.00001887" iyy="0.00094964" iyz="-0.00002958" izz="0.00464908"/>
    </inertial>
    <visual>
      <origin rpy="0 0 0" xyz="0 0 0"/>
      <geometry>
        <mesh filename="package://nimbro_op_model/mesh/nimbro_new/left_hip_link.STL"/>
      </geometry>
      <material name="black"/>
    </visual>
    <collision>
      <origin rpy="0 0 0" xyz="0 0 0"/>
      <geometry>
        <mesh filename="package://nimbro_op_model/mesh/nimbro_new/left_hip_link.STL"/>
      </geometry>
    </collision>
  </link>
  <joint name="left_hip_roll" type="continuous">
    <origin rpy="0 0 0" xyz="0 0 -0.057408771126"/>
    <parent link="left_hip_yaw_link"/>
    <child link="left_hip_roll_link"/>
    <axis xyz="1 0 0"/>
  </joint>
  <link name="left_thigh_link">
    <inertial>
      <origin rpy="0 0 0" xyz="0.01970977 -0.00209924 -0.12743050"/>
      <mass value="0.45418350"/>
      <inertia ixx="0.00608556" ixy="0.00000866" ixz="-0.00001934" iyy="0.00585037" iyz="0.00010098" izz="0.00141334"/>
    </inertial>
    <!-- Use parallel link visuals<visual>
				<origin xyz="0 0 0" rpy="0 0 0" />
				<geometry>
					<mesh filename="package://nimbro_op_model/mesh/${display_variant}/left_thigh_link.STL" />
				</geometry>
				<material name="white" />
			</visual>-->
    <collision>
      <origin rpy="0 0 0" xyz="0 0 0"/>
      <geometry>
        <mesh filename="package://nimbro_op_model/mesh/nimbro_new/left_thigh_link.STL"/>
      </geometry>
    </collision>
  </link>
  <joint name="left_hip_pitch" type="continuous">
    <origin rpy="0 0 0" xyz="-0.00255 0.1014 0"/>
    <parent link="left_hip_roll_link"/>
    <child link="left_thigh_link"/>
    <axis xyz="0 1 0"/>
  </joint>
  <link name="left_shank_link">
    <inertial>
      <origin rpy="0 0 0" xyz="0.01748220 -0.00011553 -0.10458745"/>
      <mass value="0.31908091"/>
      <inertia ixx="0.00321630" ixy="-0.00000043" ixz="-0.00009814" iyy="0.00296736" iyz="-0.00000589" izz="0.00064089"/>
    </inertial>
    <!-- Use parallel link visuals<visual>
				<origin xyz="0 0 0" rpy="0 0 0" />
				<geometry>
					<mesh filename="package://nimbro_op_model/mesh/${display_variant}/left_shank_link.STL" />
				</geometry>
				<material name="white" />
			</visual>-->
    <collision>
      <origin rpy="0 0 0" xyz="0 0 0"/>
      <geometry>
        <mesh filename="package://nimbro_op_model/mesh/nimbro_new/left_shank_link.STL"/>
      </geometry>
    </collision>
  </link>
  <joint name="left_knee_pitch" type="continuous">
    <origin rpy="0 0 0" xyz="0 0 -0.27"/>
    <parent link="left_thigh_link"/>
    <child link="left_shank_link"/>
    <axis xyz="0 1 0"/>
  </joint>
  <link name="left_ankle_link">
    <inertial>
      <origin rpy="0 0 0" xyz="0.02809098 0.00090749 -0.06129945"/>
      <mass value="0.27529515"/>
      <inertia ixx="0.00020316" ixy="-0.00000124" ixz="0.00008239" iyy="0.00050134" iyz="-0.00001107" izz="0.00049366"/>
    </inertial>
    <!-- Use parallel link visuals<visual>
				<origin xyz="0 0 0" rpy="0 0 0" />
				<geometry>
					<mesh filename="package://nimbro_op_model/mesh/${display_variant}/left_ankle_link.STL" />
				</geometry>
				<material name="white" />
			</visual>-->
    <collision>
      <origin rpy="0 0 0" xyz="0 0 0"/>
      <geometry>
        <mesh filename="package://nimbro_op_model/mesh/nimbro_new/left_ankle_link.STL"/>
      </geometry>
    </collision>
  </link>
  <joint name="left_ankle_pitch" type="continuous">
    <origin rpy="0 0 0" xyz="0 0 -0.27"/>
    <parent link="left_shank_link"/>
    <child link="left_ankle_link"/>
    <axis xyz="0 1 0"/>
  </joint>
  <link name="left_foot_link">
		</link>
  <joint name="left_ankle_roll" type="continuous">
    <origin rpy="0 0 0" xyz="0 0 0"/>
    <parent link="left_ankle_link"/>
    <child link="left_foot_link"/>
    <axis xyz="1 0 0"/>
  </joint>
  <link name="left_foot_plane_link">
		</link>
  <joint name="left_foot_plane_joint" type="fixed">
    <origin rpy="0 0 0" xyz="0.04562 0 -0.055"/>
    <parent link="left_foot_link"/>
    <child link="left_foot_plane_link"/>
  </joint>
  <!-- **************** RIGHT ARM **************** -->
  <link name="right_shoulder_pitch_link">
    <inertial>
      <origin rpy="0 0 0" xyz="0.00165563 -0.07432328 -0.13752631"/>
      <mass value="0.04859780"/>
      <inertia ixx="0.00944004" ixy="0.00000012" ixz="0.00000046" iyy="0.00877735" iyz="-0.00233820" izz="0.00076229"/>
    </inertial>
    <visual>
      <origin rpy="0 0 0" xyz="0 0 0"/>
      <geometry>
        <mesh filename="package://nimbro_op_model/mesh/nimbro_new/left_shoulder_link.STL" scale="1.0 -1.0 1.0"/>
      </geometry>
      <material name="white"/>
    </visual>
    <collision>
      <origin rpy="0 0 0" xyz="0 0 0"/>
      <geometry>
        <mesh filename="package://nimbro_op_model/mesh/nimbro_new/left_shoulder_link.STL" scale="1.0 -1.0 1.0"/>
      </geometry>
    </collision>
  </link>
  <joint name="right_shoulder_pitch" type="continuous">
    <origin rpy="-0.174532925 0 0" xyz="0 -0.09177824488 0.26148499688"/>
    <parent link="trunk_link"/>
    <child link="right_shoulder_pitch_link"/>
    <axis xyz="0 1 0"/>
  </joint>
  <link name="right_upper_arm_link">
		</link>
  <joint name="right_shoulder_roll" type="continuous">
    <origin rpy="0 0 0" xyz="0 0 0"/>
    <parent link="right_shoulder_pitch_link"/>
    <child link="right_upper_arm_link"/>
    <axis xyz="1 0 0"/>
  </joint>
  <link name="right_lower_arm_link">
		</link>
  <joint name="right_elbow_pitch" type="continuous">
    <origin rpy="0 0 0" xyz="0 0 0"/>
    <parent link="right_upper_arm_link"/>
    <child link="right_lower_arm_link"/>
    <axis xyz="0 1 0"/>
  </joint>
  <link name="right_hand_eef_link">
		</link>
  <joint name="right_hand_eef_joint" type="fixed">
    <origin rpy="0 0 0" xyz="0.0 0.0 -0.25"/>
    <parent link="right_lower_arm_link"/>
    <child link="right_hand_eef_link"/>
  </joint>
  <!-- **************** LEFT ARM **************** -->
  <link name="left_shoulder_pitch_link">
    <inertial>
      <origin rpy="0 0 0" xyz="0.00165563 0.07432328 -0.13752631"/>
      <mass value="0.04859780"/>
      <inertia ixx="0.00943885" ixy="-0.00002743" ixz="0.00010178" iyy="0.00877735" iyz="0.00233804" izz="0.00076348"/>
    </inertial>
    <visual>
      <origin rpy="0 0 0" xyz="0 0 0"/>
      <geometry>
        <mesh filename="package://nimbro_op_model/mesh/nimbro_new/left_shoulder_link.STL"/>
      </geometry>
      <material name="white"/>
    </visual>
    <collision>
      <origin rpy="0 0 0" xyz="0 0 0"/>
      <geometry>
        <mesh filename="package://nimbro_op_model/mesh/nimbro_new/left_shoulder_link.STL"/>
      </geometry>
    </collision>
  </link>
  <joint name="left_shoulder_pitch" type="continuous">
    <origin rpy="0.174532925 0 0" xyz="0 0.09177824488 0.26148499688"/>
    <parent link="trunk_link"/>
    <child link="left_shoulder_pitch_link"/>
    <axis xyz="0 1 0"/>
  </joint>
  <link name="left_upper_arm_link">
		</link>
  <joint name="left_shoulder_roll" type="continuous">
    <origin rpy="0 0 0" xyz="0 0 0"/>
    <parent link="left_shoulder_pitch_link"/>
    <child link="left_upper_arm_link"/>
    <axis xyz="1 0 0"/>
  </joint>
  <link name="left_lower_arm_link">
		</link>
  <joint name="left_elbow_pitch" type="continuous">
    <origin rpy="0 0 0" xyz="0 0 0"/>
    <parent link="left_upper_arm_link"/>
    <child link="left_lower_arm_link"/>
    <axis xyz="0 1 0"/>
  </joint>
  <link name="left_hand_eef_link">
		</link>
  <joint name="left_hand_eef_joint" type="fixed">
    <origin rpy="0 0 0" xyz="0.0 0.0 -0.25"/>
    <parent link="left_lower_arm_link"/>
    <child link="left_hand_eef_link"/>
  </joint>
  <!-- **************** HEAD **************** -->
  <link name="neck_link">
		</link>
  <joint name="neck_yaw" type="continuous">
    <origin rpy="0 0 0" xyz="0.04 0 0.3098"/>
    <parent link="trunk_link"/>
    <child link="neck_link"/>
    <axis xyz="0 0 1"/>
  </joint>
  <link name="head_link">
		</link>
  <joint name="head_pitch" type="continuous">
    <origin rpy="0 0 0" xyz="0 0 0.04975"/>
    <parent link="neck_link"/>
    <child link="head_link"/>
    <axis xyz="0 1 0"/>
  </joint>
  <link name="camera_optical">
		</link>
  <joint name="camera_joint" type="fixed">
    <origin rpy="-1.7453292519943295 0 -1.5707963267948966" xyz="0.04488 -0.0375 0.08231"/>
    <parent link="head_link"/>
    <child link="camera_optical"/>
  </joint>
  <link name="camera_optical_1">
		</link>
  <joint name="camera_joint_1" type="fixed">
    <origin rpy="-1.7453292519943295 0 -1.5707963267948966" xyz="0.05374 0 0.09201"/>
    <parent link="head_link"/>
    <child link="camera_optical_1"/>
  </joint>
  <!-- Parallel Kinematics visuals only, begin in hip rolls-->
  <!-- Right Leg-->
  <joint name="parallel_right_thigh_pitch" type="continuous">
    <origin rpy="0 0 0" xyz="-0.00255 -0.1014 0"/>
    <parent link="right_hip_roll_link"/>
    <child link="parallel_right_thigh_front_link"/>
    <axis xyz="0 1 0"/>
  </joint>
  <link name="parallel_right_thigh_front_link">
    <visual>
      <origin rpy="0 0 0" xyz="0 0 0"/>
      <geometry>
        <mesh filename="package://nimbro_op_model/mesh/nimbro_new/left_thigh_link.STL" scale="1.0 -1.0 1.0"/>
      </geometry>
      <material name="white"/>
    </visual>
  </link>
  <joint name="parallel_right_thigh_pitch_mimic1" type="continuous">
    <origin rpy="0 0 0" xyz="0 0 -0.27"/>
    <parent link="parallel_right_thigh_front_link"/>
    <child link="parallel_right_knee_front_link"/>
    <axis xyz="0 1 0"/>
    <mimic joint="parallel_right_thigh_pitch" multiplier="-1" offset="0"/>
  </joint>
  <link name="parallel_right_knee_front_link">
    <visual>
      <origin rpy="0 0 0" xyz="0 0 0"/>
      <geometry>
        <mesh filename="package://nimbro_op_model/mesh/nimbro_new/left_knee_link.STL" scale="1.0 -1.0 1.0"/>
      </geometry>
      <material name="white"/>
    </visual>
  </link>
  <joint name="parallel_right_shank_pitch" type="continuous">
    <origin rpy="0 0 0" xyz="0 0 0"/>
    <parent link="parallel_right_knee_front_link"/>
    <child link="parallel_right_shank_front_link"/>
    <axis xyz="0 1 0"/>
  </joint>
  <link name="parallel_right_shank_front_link">
    <visual>
      <origin rpy="0 0 0" xyz="0 0 0"/>
      <geometry>
        <mesh filename="package://nimbro_op_model/mesh/nimbro_new/left_shank_link.STL" scale="1.0 -1.0 1.0"/>
      </geometry>
      <material name="white"/>
    </visual>
  </link>
  <joint name="parallel_right_shank_pitch_mimic1" type="continuous">
    <origin rpy="0 0 0" xyz="0 0 -0.27"/>
    <parent link="parallel_right_shank_front_link"/>
    <child link="parallel_right_ankle_link"/>
    <axis xyz="0 1 0"/>
    <mimic joint="parallel_right_shank_pitch" multiplier="-1" offset="0"/>
  </joint>
  <link name="parallel_right_ankle_link">
    <visual>
      <origin rpy="0 0 0" xyz="0 0 0"/>
      <geometry>
        <mesh filename="package://nimbro_op_model/mesh/nimbro_new/left_ankle_link.STL" scale="1.0 -1.0 1.0"/>
      </geometry>
      <material name="white"/>
    </visual>
  </link>
  <joint name="parallel_right_ankle_roll" type="continuous">
    <origin rpy="0 0 0" xyz="0 0 0"/>
    <parent link="parallel_right_ankle_link"/>
    <child link="parallel_right_foot_link"/>
    <axis xyz="1 0 0"/>
  </joint>
  <link name="parallel_right_foot_link">
		</link>
  <joint name="parallel_right_foot_plane_joint" type="fixed">
    <origin rpy="0 0 0" xyz="0.04562 0 -0.055"/>
    <parent link="parallel_right_foot_link"/>
    <child link="parallel_right_foot_plane_link"/>
  </joint>
  <link name="parallel_right_foot_plane_link">
		</link>
  <!-- back chain-->
  <joint name="parallel_right_thigh_pitch_mimic2" type="continuous">
    <origin rpy="0 0 0" xyz="-0.036 0 -0.04755"/>
    <parent link="right_hip_roll_link"/>
    <child link="parallel_right_thigh_back_link"/>
    <axis xyz="0 1 0"/>
    <mimic joint="parallel_right_thigh_pitch" multiplier="1" offset="0"/>
  </joint>
  <link name="parallel_right_thigh_back_link">

		</link>
  <joint name="parallel_right_thigh_pitch_mimic3" type="continuous">
    <origin rpy="0 0 0" xyz="0 0 -0.27"/>
    <parent link="parallel_right_thigh_back_link"/>
    <child link="parallel_right_knee_back_link"/>
    <axis xyz="0 1 0"/>
    <mimic joint="parallel_right_thigh_pitch" multiplier="-1" offset="0"/>
  </joint>
  <link name="parallel_right_knee_back_link">
		</link>
  <joint name="parallel_right_shank_pitch_mimic2" type="continuous">
    <origin rpy="0 0 0" xyz="0 0 -0.0485"/>
    <parent link="parallel_right_knee_back_link"/>
    <child link="parallel_right_shank_back_link"/>
    <axis xyz="0 1 0"/>
    <mimic joint="parallel_right_shank_pitch" multiplier="1" offset="0"/>
  </joint>
  <link name="parallel_right_shank_back_link">
        </link>
  <!-- Left Leg-->
  <!-- Parallel Kinematics visuals only, begin in hip rolls-->
  <!-- Right Leg-->
  <joint name="parallel_left_thigh_pitch" type="continuous">
    <origin rpy="0 0 0" xyz="-0.00255 0.1014 0"/>
    <parent link="left_hip_roll_link"/>
    <child link="parallel_left_thigh_front_link"/>
    <axis xyz="0 1 0"/>
  </joint>
  <link name="parallel_left_thigh_front_link">
    <visual>
      <origin rpy="0 0 0" xyz="0 0 0"/>
      <geometry>
        <mesh filename="package://nimbro_op_model/mesh/nimbro_new/left_thigh_link.STL"/>
      </geometry>
      <material name="white"/>
    </visual>
  </link>
  <joint name="parallel_left_thigh_pitch_mimic1" type="continuous">
    <origin rpy="0 0 0" xyz="0 0 -0.27"/>
    <parent link="parallel_left_thigh_front_link"/>
    <child link="parallel_left_knee_front_link"/>
    <axis xyz="0 1 0"/>
    <mimic joint="parallel_left_thigh_pitch" multiplier="-1" offset="0"/>
  </joint>
  <link name="parallel_left_knee_front_link">
    <visual>
      <origin rpy="0 0 0" xyz="0 0 0"/>
      <geometry>
        <mesh filename="package://nimbro_op_model/mesh/nimbro_new/left_knee_link.STL"/>
      </geometry>
      <material name="white"/>
    </visual>
  </link>
  <joint name="parallel_left_shank_pitch" type="continuous">
    <origin rpy="0 0 0" xyz="0 0 0"/>
    <parent link="parallel_left_knee_front_link"/>
    <child link="parallel_left_shank_front_link"/>
    <axis xyz="0 1 0"/>
  </joint>
  <link name="parallel_left_shank_front_link">
    <visual>
      <origin rpy="0 0 0" xyz="0 0 0"/>
      <geometry>
        <mesh filename="package://nimbro_op_model/mesh/nimbro_new/left_shank_link.STL"/>
      </geometry>
      <material name="white"/>
    </visual>
  </link>
  <joint name="parallel_left_shank_pitch_mimic1" type="continuous">
    <origin rpy="0 0 0" xyz="0 0 -0.27"/>
    <parent link="parallel_left_shank_front_link"/>
    <child link="parallel_left_ankle_link"/>
    <axis xyz="0 1 0"/>
    <mimic joint="parallel_left_shank_pitch" multiplier="-1" offset="0"/>
  </joint>
  <link name="parallel_left_ankle_link">
    <visual>
      <origin rpy="0 0 0" xyz="0 0 0"/>
      <geometry>
        <mesh filename="package://nimbro_op_model/mesh/nimbro_new/left_ankle_link.STL"/>
      </geometry>
      <material name="white"/>
    </visual>
  </link>
  <joint name="parallel_left_ankle_roll" type="continuous">
    <origin rpy="0 0 0" xyz="0 0 0"/>
    <axis xyz="1 0 0"/>
    <parent link="parallel_left_ankle_link"/>
    <child link="parallel_left_foot_link"/>
    <axis xyz="1 0 0"/>
  </joint>
  <link name="parallel_left_foot_link">
		</link>
  <joint name="parallel_left_foot_plane_joint" type="fixed">
    <origin rpy="0 0 0" xyz="0.04562 0 -0.055"/>
    <parent link="parallel_left_foot_link"/>
    <child link="parallel_left_foot_plane_link"/>
  </joint>
  <link name="parallel_left_foot_plane_link">
		</link>
  <!-- back chain-->
  <joint name="parallel_left_thigh_pitch_mimic2" type="continuous">
    <origin rpy="0 0 0" xyz="-0.036 0 -0.04755"/>
    <parent link="left_hip_roll_link"/>
    <child link="parallel_left_thigh_back_link"/>
    <axis xyz="0 1 0"/>
    <mimic joint="parallel_left_thigh_pitch" multiplier="1" offset="0"/>
  </joint>
  <link name="parallel_left_thigh_back_link">
		</link>
  <joint name="parallel_left_thigh_pitch_mimic3" type="continuous">
    <origin rpy="0 0 0" xyz="0 0 -0.26"/>
    <parent link="parallel_left_thigh_back_link"/>
    <child link="parallel_left_knee_back_link"/>
    <axis xyz="0 1 0"/>
    <mimic joint="parallel_left_thigh_pitch" multiplier="-1" offset="0"/>
  </joint>
  <link name="parallel_left_knee_back_link">
		</link>
  <joint name="parallel_left_shank_pitch_mimic2" type="continuous">
    <origin rpy="0 0 0" xyz="0 0 -0.0485"/>
    <parent link="parallel_left_knee_back_link"/>
    <child link="parallel_left_shank_back_link"/>
    <axis xyz="0 1 0"/>
    <mimic joint="parallel_left_shank_pitch" multiplier="1" offset="0"/>
  </joint>
  <link name="parallel_left_shank_back_link">
		</link>
  <!-- Transmissions -->
  <transmission name="right_hip_yaw_transmission">
    <type>transmission_interface/SimpleTransmission</type>
    <joint name="right_hip_yaw">
      <hardwareInterface>hardware_interface/EffortJointInterface</hardwareInterface>
    </joint>
    <actuator name="right_hip_yaw">
      <mechanicalReduction>1</mechanicalReduction>
    </actuator>
  </transmission>
  <transmission name="right_hip_roll_transmission">
    <type>transmission_interface/SimpleTransmission</type>
    <joint name="right_hip_roll">
      <hardwareInterface>hardware_interface/EffortJointInterface</hardwareInterface>
    </joint>
    <actuator name="right_hip_roll">
      <mechanicalReduction>1</mechanicalReduction>
    </actuator>
  </transmission>
  <transmission name="right_hip_pitch_transmission">
    <type>transmission_interface/SimpleTransmission</type>
    <joint name="right_hip_pitch">
      <hardwareInterface>hardware_interface/EffortJointInterface</hardwareInterface>
    </joint>
    <actuator name="right_hip_pitch">
      <mechanicalReduction>1</mechanicalReduction>
    </actuator>
  </transmission>
  <transmission name="right_knee_pitch_transmission">
    <type>transmission_interface/SimpleTransmission</type>
    <joint name="right_knee_pitch">
      <hardwareInterface>hardware_interface/EffortJointInterface</hardwareInterface>
    </joint>
    <actuator name="right_knee_pitch">
      <mechanicalReduction>1</mechanicalReduction>
    </actuator>
  </transmission>
  <transmission name="right_ankle_pitch_transmission">
    <type>transmission_interface/SimpleTransmission</type>
    <joint name="right_ankle_pitch">
      <hardwareInterface>hardware_interface/EffortJointInterface</hardwareInterface>
    </joint>
    <actuator name="right_ankle_pitch">
      <mechanicalReduction>1</mechanicalReduction>
    </actuator>
  </transmission>
  <transmission name="right_ankle_roll_transmission">
    <type>transmission_interface/SimpleTransmission</type>
    <joint name="right_ankle_roll">
      <hardwareInterface>hardware_interface/EffortJointInterface</hardwareInterface>
    </joint>
    <actuator name="right_ankle_roll">
      <mechanicalReduction>1</mechanicalReduction>
    </actuator>
  </transmission>
  <transmission name="parallel_right_thigh_pitch_transmission">
    <type>transmission_interface/SimpleTransmission</type>
    <joint name="parallel_right_thigh_pitch">
      <hardwareInterface>hardware_interface/EffortJointInterface</hardwareInterface>
    </joint>
    <actuator name="parallel_right_thigh_pitch">
      <mechanicalReduction>1</mechanicalReduction>
    </actuator>
  </transmission>
  <transmission name="parallel_right_shank_pitch_transmission">
    <type>transmission_interface/SimpleTransmission</type>
    <joint name="parallel_right_shank_pitch">
      <hardwareInterface>hardware_interface/EffortJointInterface</hardwareInterface>
    </joint>
    <actuator name="parallel_right_shank_pitch">
      <mechanicalReduction>1</mechanicalReduction>
    </actuator>
  </transmission>
  <transmission name="parallel_right_ankle_roll_transmission">
    <type>transmission_interface/SimpleTransmission</type>
    <joint name="parallel_right_ankle_roll">
      <hardwareInterface>hardware_interface/EffortJointInterface</hardwareInterface>
    </joint>
    <actuator name="parallel_right_ankle_roll">
      <mechanicalReduction>1</mechanicalReduction>
    </actuator>
  </transmission>
  <transmission name="left_hip_yaw_transmission">
    <type>transmission_interface/SimpleTransmission</type>
    <joint name="left_hip_yaw">
      <hardwareInterface>hardware_interface/EffortJointInterface</hardwareInterface>
    </joint>
    <actuator name="left_hip_yaw">
      <mechanicalReduction>1</mechanicalReduction>
    </actuator>
  </transmission>
  <transmission name="left_hip_roll_transmission">
    <type>transmission_interface/SimpleTransmission</type>
    <joint name="left_hip_roll">
      <hardwareInterface>hardware_interface/EffortJointInterface</hardwareInterface>
    </joint>
    <actuator name="left_hip_roll">
      <mechanicalReduction>1</mechanicalReduction>
    </actuator>
  </transmission>
  <transmission name="left_hip_pitch_transmission">
    <type>transmission_interface/SimpleTransmission</type>
    <joint name="left_hip_pitch">
      <hardwareInterface>hardware_interface/EffortJointInterface</hardwareInterface>
    </joint>
    <actuator name="left_hip_pitch">
      <mechanicalReduction>1</mechanicalReduction>
    </actuator>
  </transmission>
  <transmission name="left_knee_pitch_transmission">
    <type>transmission_interface/SimpleTransmission</type>
    <joint name="left_knee_pitch">
      <hardwareInterface>hardware_interface/EffortJointInterface</hardwareInterface>
    </joint>
    <actuator name="left_knee_pitch">
      <mechanicalReduction>1</mechanicalReduction>
    </actuator>
  </transmission>
  <transmission name="left_ankle_pitch_transmission">
    <type>transmission_interface/SimpleTransmission</type>
    <joint name="left_ankle_pitch">
      <hardwareInterface>hardware_interface/EffortJointInterface</hardwareInterface>
    </joint>
    <actuator name="left_ankle_pitch">
      <mechanicalReduction>1</mechanicalReduction>
    </actuator>
  </transmission>
  <transmission name="left_ankle_roll_transmission">
    <type>transmission_interface/SimpleTransmission</type>
    <joint name="left_ankle_roll">
      <hardwareInterface>hardware_interface/EffortJointInterface</hardwareInterface>
    </joint>
    <actuator name="left_ankle_roll">
      <mechanicalReduction>1</mechanicalReduction>
    </actuator>
  </transmission>
  <transmission name="parallel_left_thigh_pitch_transmission">
    <type>transmission_interface/SimpleTransmission</type>
    <joint name="parallel_left_thigh_pitch">
      <hardwareInterface>hardware_interface/EffortJointInterface</hardwareInterface>
    </joint>
    <actuator name="parallel_left_thigh_pitch">
      <mechanicalReduction>1</mechanicalReduction>
    </actuator>
  </transmission>
  <transmission name="parallel_left_shank_pitch_transmission">
    <type>transmission_interface/SimpleTransmission</type>
    <joint name="parallel_left_shank_pitch">
      <hardwareInterface>hardware_interface/EffortJointInterface</hardwareInterface>
    </joint>
    <actuator name="parallel_left_shank_pitch">
      <mechanicalReduction>1</mechanicalReduction>
    </actuator>
  </transmission>
  <transmission name="parallel_left_ankle_roll_transmission">
    <type>transmission_interface/SimpleTransmission</type>
    <joint name="parallel_left_ankle_roll">
      <hardwareInterface>hardware_interface/EffortJointInterface</hardwareInterface>
    </joint>
    <actuator name="parallel_left_ankle_roll">
      <mechanicalReduction>1</mechanicalReduction>
    </actuator>
  </transmission>
  <transmission name="right_shoulder_pitch_transmission">
    <type>transmission_interface/SimpleTransmission</type>
    <joint name="right_shoulder_pitch">
      <hardwareInterface>hardware_interface/EffortJointInterface</hardwareInterface>
    </joint>
    <actuator name="right_shoulder_pitch">
      <mechanicalReduction>1</mechanicalReduction>
    </actuator>
  </transmission>
  <transmission name="right_shoulder_roll_transmission">
    <type>transmission_interface/SimpleTransmission</type>
    <joint name="right_shoulder_roll">
      <hardwareInterface>hardware_interface/EffortJointInterface</hardwareInterface>
    </joint>
    <actuator name="right_shoulder_roll">
      <mechanicalReduction>1</mechanicalReduction>
    </actuator>
  </transmission>
  <transmission name="right_elbow_pitch_transmission">
    <type>transmission_interface/SimpleTransmission</type>
    <joint name="right_elbow_pitch">
      <hardwareInterface>hardware_interface/EffortJointInterface</hardwareInterface>
    </joint>
    <actuator name="right_elbow_pitch">
      <mechanicalReduction>1</mechanicalReduction>
    </actuator>
  </transmission>
  <transmission name="left_shoulder_pitch_transmission">
    <type>transmission_interface/SimpleTransmission</type>
    <joint name="left_shoulder_pitch">
      <hardwareInterface>hardware_interface/EffortJointInterface</hardwareInterface>
    </joint>
    <actuator name="left_shoulder_pitch">
      <mechanicalReduction>1</mechanicalReduction>
    </actuator>
  </transmission>
  <transmission name="left_shoulder_roll_transmission">
    <type>transmission_interface/SimpleTransmission</type>
    <joint name="left_shoulder_roll">
      <hardwareInterface>hardware_interface/EffortJointInterface</hardwareInterface>
    </joint>
    <actuator name="left_shoulder_roll">
      <mechanicalReduction>1</mechanicalReduction>
    </actuator>
  </transmission>
  <transmission name="left_elbow_pitch_transmission">
    <type>transmission_interface/SimpleTransmission</type>
    <joint name="left_elbow_pitch">
      <hardwareInterface>hardware_interface/EffortJointInterface</hardwareInterface>
    </joint>
    <actuator name="left_elbow_pitch">
      <mechanicalReduction>1</mechanicalReduction>
    </actuator>
  </transmission>
  <transmission name="neck_yaw_transmission">
    <type>transmission_interface/SimpleTransmission</type>
    <joint name="neck_yaw">
      <hardwareInterface>hardware_interface/EffortJointInterface</hardwareInterface>
    </joint>
    <actuator name="neck_yaw">
      <mechanicalReduction>1</mechanicalReduction>
    </actuator>
  </transmission>
  <transmission name="head_pitch_transmission">
    <type>transmission_interface/SimpleTransmission</type>
    <joint name="head_pitch">
      <hardwareInterface>hardware_interface/EffortJointInterface</hardwareInterface>
    </joint>
    <actuator name="head_pitch">
      <mechanicalReduction>1</mechanicalReduction>
    </actuator>
  </transmission>
  <!-- Gazebo configuration -->
  <gazebo>
    <plugin filename="libgazebo_ros_control.so" name="gazebo_ros_control">
      <robotNamespace>/nimbro_op</robotNamespace>
    </plugin>
  </gazebo>
  <!-- Gazebo links -->
  <gazebo reference="trunk_link">
    <material>Gazebo/White</material>
  </gazebo>
  <gazebo reference="left_hip_yaw_link">
    <material>Gazebo/White</material>
  </gazebo>
  <gazebo reference="left_hip_roll_link">
    <material>Gazebo/White</material>
  </gazebo>
  <gazebo reference="left_thigh_link">
    <material>Gazebo/White</material>
  </gazebo>
  <gazebo reference="left_shank_link">
    <material>Gazebo/White</material>
  </gazebo>
  <gazebo reference="left_ankle_link">
    <material>Gazebo/White</material>
  </gazebo>
  <gazebo reference="left_foot_link">
    <material>Gazebo/White</material>
    <kp>1000000.0</kp>
    <kd>100.0</kd>
    <mu1>1.0</mu1>
    <mu2>1.0</mu2>
    <fdir1>1 0 0</fdir1>
    <maxVel>1.0</maxVel>
    <minDepth>0.00</minDepth>
  </gazebo>
  <gazebo reference="left_shoulder_pitch_link">
    <material>Gazebo/White</material>
  </gazebo>
  <gazebo reference="right_hip_yaw_link">
    <material>Gazebo/White</material>
  </gazebo>
  <gazebo reference="right_hip_roll_link">
    <material>Gazebo/White</material>
  </gazebo>
  <gazebo reference="right_thigh_link">
    <material>Gazebo/White</material>
  </gazebo>
  <gazebo reference="right_shank_link">
    <material>Gazebo/White</material>
  </gazebo>
  <gazebo reference="right_ankle_link">
    <material>Gazebo/White</material>
  </gazebo>
  <gazebo reference="right_foot_link">
    <material>Gazebo/White</material>
    <kp>1000000.0</kp>
    <kd>100.0</kd>
    <mu1>1.0</mu1>
    <mu2>1.0</mu2>
    <fdir1>1 0 0</fdir1>
    <maxVel>1.0</maxVel>
    <minDepth>0.00</minDepth>
  </gazebo>
  <gazebo reference="right_shoulder_pitch_link">
    <material>Gazebo/White</material>
  </gazebo>
</robot>

